<robot name="my_robot">
  <!-- World Link -->
  <link name="world"/>

  <!-- Base Link -->
  <link name="base_link">
    <visual>
      <geometry>
        <box size="0.1 0.1 0.02"/>
      </geometry>
      <material name="blue"/>
    </visual>
    <collision>
      <geometry>
        <box size="0.1 0.1 0.02"/>
      </geometry>
    </collision>
  </link>

  <!-- World Joint -->
  <joint name="world_joint" type="fixed">
    <parent link="world"/>
    <child link="base_link"/>
    <origin xyz="0 0 0" rpy="0 0 0"/>
  </joint>

  <!-- Pan Link -->
  <link name="pan_link">
    <visual>
      <geometry>
        <cylinder radius="0.02" length="0.04"/>
      </geometry>
      <origin xyz="0 0 0.02" rpy="0 0 0"/>
      <material name="green"/>
    </visual>
    <collision>
      <geometry>
        <cylinder radius="0.02" length="0.04"/>
      </geometry>
      <origin xyz="0 0 0.02" rpy="0 0 0"/>
    </collision>
  </link>

  <!-- Tilt Link -->
  <link name="tilt_link">
    <visual>
      <geometry>
        <box size="0.04 0.04 0.04"/>
      </geometry>
      <origin xyz="0 0 0.02" rpy="0 0 0"/>
      <material name="red"/>
    </visual>
    <collision>
      <geometry>
        <box size="0.04 0.04 0.04"/>
      </geometry>
      <origin xyz="0 0 0.02" rpy="0 0 0"/>
    </collision>
  </link>

  <!-- Camera Link -->
  <link name="camera_link">
    <visual>
      <geometry>
        <box size="0.04 0.02 0.02"/>
      </geometry>
      <material name="black"/>
    </visual>
    <collision>
      <geometry>
        <box size="0.04 0.02 0.02"/>
      </geometry>
    </collision>
  </link>

  <!-- Pan Joint -->
  <joint name="pan_joint" type="revolute">
    <parent link="base_link"/>
    <child link="pan_link"/>
    <origin xyz="0 0 0.036" rpy="0 0 0"/>
    <axis xyz="0 0 1"/>
    <limit lower="-3.1416" upper="3.1416" effort="1.0" velocity="1.0"/>
  </joint>

  <!-- Tilt Joint -->
  <joint name="tilt_joint" type="revolute">
    <parent link="pan_link"/>
    <child link="tilt_link"/>
    <origin xyz="0 0.015 0.025" rpy="0 0 0"/>
    <axis xyz="0 1 0"/>
    <limit lower="-1.5708" upper="1.5708" effort="1.0" velocity="1.0"/>
  </joint>

  <!-- Camera Joint -->
  <joint name="camera_joint" type="fixed">
    <parent link="tilt_link"/>
    <child link="camera_link"/>
    <origin xyz="0.02 0.02 0" rpy="0 0 0"/>
  </joint>
</robot>